Job started on Thu Nov  7 11:10:29 UTC 2024\n
concurrent.futures.process._RemoteTraceback: 
"""
Traceback (most recent call last):
  File "/scratch_dgxl/as5023/conda/miniconda3/envs/IRP/lib/python3.11/concurrent/futures/process.py", line 261, in _process_worker
    r = call_item.fn(*call_item.args, **call_item.kwargs)
        ^^^^^^^^^^^^^^^^^^^^^^^^^^^^^^^^^^^^^^^^^^^^^^^^^
  File "/scratch_dgxl/as5023/ardan-S/Lunar_point_model/data_processing/utils/load_dfs.py", line 93, in load_lro_df
    os.mkdir(data_dict['save_path']) if not os.path.exists(data_dict['save_path']) else None
    ^^^^^^^^^^^^^^^^^^^^^^^^^^^^^^^^
FileNotFoundError: [Errno 2] No such file or directory: '../../data/CSVs/raw/Diviner'
"""

The above exception was the direct cause of the following exception:

Traceback (most recent call last):
  File "/scratch_dgxl/as5023/ardan-S/Lunar_point_model/data_processing/jobscripts/../process_data.py", line 81, in <module>
    main(args)
  File "/scratch_dgxl/as5023/ardan-S/Lunar_point_model/data_processing/jobscripts/../process_data.py", line 34, in main
    raise e
  File "/scratch_dgxl/as5023/ardan-S/Lunar_point_model/data_processing/jobscripts/../process_data.py", line 30, in main
    future.result()
  File "/scratch_dgxl/as5023/conda/miniconda3/envs/IRP/lib/python3.11/concurrent/futures/_base.py", line 449, in result
    return self.__get_result()
           ^^^^^^^^^^^^^^^^^^^
  File "/scratch_dgxl/as5023/conda/miniconda3/envs/IRP/lib/python3.11/concurrent/futures/_base.py", line 401, in __get_result
    raise self._exception
FileNotFoundError: [Errno 2] No such file or directory: '../../data/CSVs/raw/Diviner'
Job finished on Thu Nov  7 11:10:31 UTC 2024
Total runtime: 0 minutes and 2 seconds
